Workbook

Sheet PRODUCTOS
A1: CODIGO | B1: ORD | C1: RUBRO | D1: PRECIO | E1: NEW | F1: MELI | G1: CARPETA | H1: EAN | I1: LINEA1 | J1: LINEA2 | K1: LINEA3 | L1: LINEA4
A2: D-AS100 | C2: Aspiradoras | D2: =IFERROR(VLOOKUP(A2,DAIHATSU!A:B,2,FALSE),"AGOTADO") -> 24900 | G2: FOTOS1 | H2: =IFERROR(VLOOKUP(A2,EAN!A:C,3,FALSE),"") -> '7799199013900 | I2: Aspiradora de auto con cable | J2: Capacidad: 320 ml | K2: Potencia: 90W | L2: Voltaje: 12V (puerto encendedor del auto)
A3: D-AS101 | C3: Aspiradoras | D3: =IFERROR(VLOOKUP(A3,DAIHATSU!A:B,2,FALSE),"AGOTADO") -> 33900 | G3: FOTOS1 | H3: =IFERROR(VLOOKUP(A3,EAN!A:C,3,FALSE),"") -> '7799199013900 | I3: Aspiradora de mano inalámbrica | J3: Capacidad: 320ml | K3: Potencia: 60w | L3: Recargable mediante puerto USB
A4: D-AS102 | C4: Aspiradoras | D4: =IFERROR(VLOOKUP(A4,DAIHATSU!A:B,2,FALSE),"AGOTADO") -> 38900 | G4: FOTOS1 | H4: =IFERROR(VLOOKUP(A4,EAN!A:C,3,FALSE),"") -> '7799199013924 | I4: Aspiradora de mano inalámbrica | J4: Capacidad: 395 ml | K4: Potencia: 80W | L4: Recargable mediante puerto USB
A5: D-AS200 | C5: Aspiradoras | D5: =IFERROR(VLOOKUP(A5,DAIHATSU!A:B,2,FALSE),"AGOTADO") -> 135900 | G5: FOTOS1 | H5: =IFERROR(VLOOKUP(A5,EAN!A:C,3,FALSE),"") -> '7799199015720 | I5: Aspiradora inalámbrica Vertical y De Mano | J5: Capacidad: 500 ml | K5: Potencia: 120W | L5: Recargable mediante puerto USB
A6: D-AS201 | C6: Aspiradoras | D6: =IFERROR(VLOOKUP(A6,DAIHATSU!A:B,2,FALSE),"AGOTADO") -> 145900 | G6: FOTOS1 | H6: =IFERROR(VLOOKUP(A6,EAN!A:C,3,FALSE),"") -> '7799199015737 | I6: Aspiradora inalámbrica Vertical y De Mano | J6: Capacidad: 800ML | K6: Potencia: 120W | L6: Voltaje: 22.2Vá
A7: D-AS300 | C7: Aspiradoras | D7: =IFERROR(VLOOKUP(A7,DAIHATSU!A:B,2,FALSE),"AGOTADO") -> 57900 | G7: FOTOS1 | H7: =IFERROR(VLOOKUP(A7,EAN!A:C,3,FALSE),"") -> '7799199015744 | I7: Aspiradora Vertical con cableá | J7: Capacidad: 800ML | K7: Potencia: 600W | L7: Voltaje: 220 - 240 V - 50/60 Hz
A8: D-AS400 | C8: Aspiradoras | D8: =IFERROR(VLOOKUP(A8,DAIHATSU!A:B,2,FALSE),"AGOTADO") -> 79900 | G8: FOTOS1 | H8: =IFERROR(VLOOKUP(A8,EAN!A:C,3,FALSE),"") -> '7799199015751 | I8: Aspiradora con bolsa lavable | J8: Capacidad: 1 L | K8: Potencia: 1400W | L8: Voltaje: 220 - 240 V - 50/60 Hz
A9: D-AS500 | C9: Aspiradoras | D9: =IFERROR(VLOOKUP(A9,DAIHATSU!A:B,2,FALSE),"AGOTADO") -> 89900 | G9: FOTOS1 | H9: =IFERROR(VLOOKUP(A9,EAN!A:C,3,FALSE),"") -> '7799199015768 | I9: Aspiradora Ciclónica sin bolsa | J9: Capacidad: 1.5 L | K9: Potencia: 1400W | L9: Voltaje: 220 - 240 V - 50/60 Hz
A10: D-AU100-BK | C10: Auriculares | D10: =IFERROR(VLOOKUP(A10,DAIHATSU!A:B,2,FALSE),"AGOTADO") -> 3900 | G10: FOTOS1 | H10: =IFERROR(VLOOKUP(A10,EAN!A:C,3,FALSE),"") | I10: Auricular Con Cable, Micrófono Manos Libres | J10: Sensibilidad de 96 dB | K10: Largo Cable 1200mm. Jack: 3.5mm | L10: Frecuencia: 20Hz- 20KHz
A11: D-AU100-WE | C11: Auriculares | D11: =IFERROR(VLOOKUP(A11,DAIHATSU!A:B,2,FALSE),"AGOTADO") -> 3900 | G11: FOTOS1 | H11: =IFERROR(VLOOKUP(A11,EAN!A:C,3,FALSE),"") | I11: Auricular Con Cable, Micrófono Manos Libres | J11: Sensibilidad de 96 dB | K11: Largo Cable 1200mm. Jack: 3.5mm | L11: Frecuencia: 20Hz- 20KHz
A12: D-AU102-WE | C12: Auriculares | D12: =IFERROR(VLOOKUP(A12,DAIHATSU!A:B,2,FALSE),"AGOTADO") -> 10900 | G12: FOTOS1 | H12: =IFERROR(VLOOKUP(A12,EAN!A:C,3,FALSE),"") -> '7798019955376 | I12: Auricular Vincha | J12: Largo del cable: 1 metro | K12: Largo del cable: 1 metro | L12: Frecuencia: 20Hz- 20KHz
A13: D-AU103-BR | C13: Auriculares | D13: =IFERROR(VLOOKUP(A13,DAIHATSU!A:B,2,FALSE),"AGOTADO") -> 3900 | G13: FOTOS1 | H13: =IFERROR(VLOOKUP(A13,EAN!A:C,3,FALSE),"") | I13: Auricular Con Cable | J13: Sensibilidad. 116dB. | K13: Largo Cable 1130mm. Jack: 3.5mm | L13: Frecuencia: 20Hz- 20KHz
... A23: D-AU519-WE | C23: Auriculares | D23: =IFERROR(VLOOKUP(A23,DAIHATSU!A:B,2,FALSE),"AGOTADO") -> 19500 | G23: FOTOS1 | H23: =IFERROR(VLOOKUP(A23,EAN!A:C,3,FALSE),"") -> '7798019955417 | I23: Auricular In-Ear | J23: Alcance: 10 metros | K23: Tiempo de uso: 2-3 horas aprox. | L23: Entrada: DC5V
A24: AX-120B | C24: Calculadoras Casio | D24: =IFERROR(VLOOKUP(A24,'CALC casio'!A:B,2,FALSE),"AGOTADO") -> 27500 | G24: FOTOS1 | H24: =IFERROR(VLOOKUP(A24,EAN!A:C,3,FALSE),"") | I24: Calculadora de Escritorio CASIO | J24: 12 dígitos | K24: Medidas: 175x110,5x25mm | L24: Solar y a Pila
A25: AX-120ST | C25: Calculadoras Casio | D25: =IFERROR(VLOOKUP(A25,'CALC casio'!A:B,2,FALSE),"AGOTADO") -> 36500 | G25: FOTOS1 | H25: =IFERROR(VLOOKUP(A25,EAN!A:C,3,FALSE),"") | I25: Calculadora de Escritorio CASIO | J25: 12 dígitos | K25: Medidas: 175x110,5x25mm | L25: Solar y a Pila
A26: DX-120B | C26: Calculadoras Casio | D26: =IFERROR(VLOOKUP(A26,'CALC casio'!A:B,2,FALSE),"AGOTADO") -> 33500 | G26: FOTOS1 | H26: =IFERROR(VLOOKUP(A26,EAN!A:C,3,FALSE),"") | I26: Calculadora de Escritorio CASIO | J26: 12 dígitos | K26: Medidas: 175x129,5x33mm | L26: Solar y a Pila
A27: DX-12B-BK | C27: Calculadoras Casio | D27: =IFERROR(VLOOKUP(A27,'CALC casio'!A:B,2,FALSE),"AGOTADO") -> 30900 | G27: FOTOS1 | H27: =IFERROR(VLOOKUP(A27,EAN!A:C,3,FALSE),"") | I27: Calculadora de Escritorio CASIO | J27: 12 dígitos | K27: Medidas: 175x129,5x33mm | L27: Solar y a Pila
A28: FX-570ESPLUS2 | C28: Calculadoras Casio | D28: =IFERROR(VLOOKUP(A28,'CALC casio'!A:B,2,FALSE),"AGOTADO") -> 61900 | G28: FOTOS1 | H28: =IFERROR(VLOOKUP(A28,EAN!A:C,3,FALSE),"") | I28: Calculadora científica CASIO | J28: 10+2 dígitos - 417 funciones | K28: Medidas: 161,5x77x13,8mm | L28: Pila
A29: FX-570ESPLUS2BU | C29: Calculadoras Casio | D29: =IFERROR(VLOOKUP(A29,'CALC casio'!A:B,2,FALSE),"AGOTADO") -> 61900 | G29: FOTOS1 | H29: =IFERROR(VLOOKUP(A29,EAN!A:C,3,FALSE),"") | I29: Calculadora científica CASIO | J29: 10+2 dígitos - 417 funciones | K29: Medidas: 161,5x77x13,8mm | L29: Pila
A30: FX-570ESPLUS2PK | C30: Calculadoras Casio | D30: =IFERROR(VLOOKUP(A30,'CALC casio'!A:B,2,FALSE),"AGOTADO") -> 61900 | G30: FOTOS1 | H30: =IFERROR(VLOOKUP(A30,EAN!A:C,3,FALSE),"") | I30: Calculadora científica CASIO | J30: 10+2 dígitos - 417 funciones | K30: Medidas: 161,5x77x13,8mm | L30: Pila
A31: FX-570LAC-W | C31: Calculadoras Casio | D31: =IFERROR(VLOOKUP(A31,'CALC casio'!A:B,2,FALSE),"AGOTADO") -> 79500 | G31: FOTOS1 | H31: =IFERROR(VLOOKUP(A31,EAN!A:C,3,FALSE),"") | I31: Calculadora científica programable CASIO | J31: 10+2 dígitos - 2900 funciones | K31: Medidas: 188,5x89x18,6mm | L31: Pila
A32: FX-82ESPLUS2 | C32: Calculadoras Casio | D32: =IFERROR(VLOOKUP(A32,'CALC casio'!A:B,2,FALSE),"AGOTADO") -> 37900 | G32: FOTOS1 | H32: =IFERROR(VLOOKUP(A32,EAN!A:C,3,FALSE),"") | I32: Calculadora científica CASIO | J32: 10+2 dígitos - 252 funciones | K32: Medidas: 161,5x77x13,8mm | L32: Pila
A33: FX-82ESPLUS2-BU | C33: Calculadoras Casio | D33: =IFERROR(VLOOKUP(A33,'CALC casio'!A:B,2,FALSE),"AGOTADO") -> 37900 | G33: FOTOS1 | H33: =IFERROR(VLOOKUP(A33,EAN!A:C,3,FALSE),"") | I33: Calculadora científica CASIO | J33: 10+2 dígitos - 252 funciones | K33: Medidas: 161,5x77x13,8mm | L33: Pila
A34: FX-82ESPLUS2-PK | C34: Calculadoras Casio | D34: =IFERROR(VLOOKUP(A34,'CALC casio'!A:B,2,FALSE),"AGOTADO") -> 37900 | G34: FOTOS1 | H34: =IFERROR(VLOOKUP(A34,EAN!A:C,3,FALSE),"") | I34: Calculadora científica CASIO | J34: 10+2 dígitos - 252 funciones | K34: Medidas: 161,5x77x13,8mm | L34: Pila
A35: FX-82LACW-W | C35: Calculadoras Casio | D35: =IFERROR(VLOOKUP(A35,'CALC casio'!A:B,2,FALSE),"AGOTADO") -> 47500 | G35: FOTOS1 | H35: =IFERROR(VLOOKUP(A35,EAN!A:C,3,FALSE),"") | I35: Calculadora científica CASIO
A36: FX-82LAPLUS2-BK | C36: Calculadoras Casio | D36: =IFERROR(VLOOKUP(A36,'CALC casio'!A:B,2,FALSE),"AGOTADO") -> 37900 | G36: FOTOS1 | H36: =IFERROR(VLOOKUP(A36,EAN!A:C,3,FALSE),"") | I36: Calculadora científica CASIO | J36: 10+2 dígitos - 252 funciones | K36: Medidas: 161,5x77x13,8mm | L36: Pila
A37: FX-82LAPLUS2-BU | C37: Calculadoras Casio | D37: =IFERROR(VLOOKUP(A37,'CALC casio'!A:B,2,FALSE),"AGOTADO") -> 37900 | G37: FOTOS1 | H37: =IFERROR(VLOOKUP(A37,EAN!A:C,3,FALSE),"") | I37: Calculadora científica CASIO | J37: 10+2 dígitos - 252 funciones | K37: Medidas: 161,5x77x13,8mm | L37: Pila
A38: FX-82LAPLUS2-PK | C38: Calculadoras Casio | D38: =IFERROR(VLOOKUP(A38,'CALC casio'!A:B,2,FALSE),"AGOTADO") -> 37900 | G38: FOTOS1 | H38: =IFERROR(VLOOKUP(A38,EAN!A:C,3,FALSE),"") | I38: Calculadora científica CASIO | J38: 10+2 dígitos - 252 funciones | K38: Medidas: 161,5x77x13,8mm | L38: Pila
A39: FX-82MS-2 | C39: Calculadoras Casio | D39: =IFERROR(VLOOKUP(A39,'CALC casio'!A:B,2,FALSE),"AGOTADO") -> 32500 | G39: FOTOS1 | H39: =IFERROR(VLOOKUP(A39,EAN!A:C,3,FALSE),"") | I39: Calculadora científica CASIO
A40: FX-95ESPLUS2 | C40: Calculadoras Casio | D40: =IFERROR(VLOOKUP(A40,'CALC casio'!A:B,2,FALSE),"AGOTADO") -> 45500 | G40: FOTOS1 | H40: =IFERROR(VLOOKUP(A40,EAN!A:C,3,FALSE),"") | I40: Calculadora científica CASIO | J40: 10+2 dígitos - 274 funciones | K40: Medidas: 161,5x77x13,8mm | L40: Pila
A41: FX-95MS-2 | C41: Calculadoras Casio | D41: =IFERROR(VLOOKUP(A41,'CALC casio'!A:B,2,FALSE),"AGOTADO") -> 42500 | G41: FOTOS1 | H41: =IFERROR(VLOOKUP(A41,EAN!A:C,3,FALSE),"") | I41: Calculadora científica CASIO
A42: FX-991ESPLUS2 | C42: Calculadoras Casio | D42: =IFERROR(VLOOKUP(A42,'CALC casio'!A:B,2,FALSE),"AGOTADO") -> 69900 | G42: FOTOS1 | H42: =IFERROR(VLOOKUP(A42,EAN!A:C,3,FALSE),"") | I42: Calculadora científica CASIO | J42: 10+2 dígitos - 274 funciones | K42: Medidas: 161,5x77x11,1mm | L42: Pila y solar
A43: FX-991ESPLUS2BU | C43: Calculadoras Casio | D43: =IFERROR(VLOOKUP(A43,'CALC casio'!A:B,2,FALSE),"AGOTADO") -> 69900 | G43: FOTOS1 | H43: =IFERROR(VLOOKUP(A43,EAN!A:C,3,FALSE),"") | I43: Calculadora científica CASIO | J43: 10+2 dígitos - 274 funciones | K43: Medidas: 161,5x77x11,1mm | L43: Pila y solar
A44: FX-991ESPLUS2PK | C44: Calculadoras Casio | D44: =IFERROR(VLOOKUP(A44,'CALC casio'!A:B,2,FALSE),"AGOTADO") -> 69900 | G44: FOTOS1 | H44: =IFERROR(VLOOKUP(A44,EAN!A:C,3,FALSE),"") | I44: Calculadora científica CASIO | J44: 10+2 dígitos - 274 funciones | K44: Medidas: 161,5x77x11,1mm | L44: Pila y solar
A45: FX-991LAPLUS2 | C45: Calculadoras Casio | D45: =IFERROR(VLOOKUP(A45,'CALC casio'!A:B,2,FALSE),"AGOTADO") -> 69900 | G45: FOTOS1 | H45: =IFERROR(VLOOKUP(A45,EAN!A:C,3,FALSE),"") | I45: Calculadora científica CASIO | J45: 10+2 dígitos - 274 funciones | K45: Medidas: 161,5x77x11,1mm | L45: Pila y solar
A46: GX-120B | C46: Calculadoras Casio | D46: =IFERROR(VLOOKUP(A46,'CALC casio'!A:B,2,FALSE),"AGOTADO") -> AGOTADO | G46: FOTOS1 | H46: =IFERROR(VLOOKUP(A46,EAN!A:C,3,FALSE),"") | I46: Calculadora de Escritorio CASIO | J46: 12 dígitos | K46: Medidas: 207,5x159,5x34mm | L46: Solar y a Pila
A47: GX-12B-BK | C47: Calculadoras Casio | D47: =IFERROR(VLOOKUP(A47,'CALC casio'!A:B,2,FALSE),"AGOTADO") -> 35500 | G47: FOTOS1 | H47: =IFERROR(VLOOKUP(A47,EAN!A:C,3,FALSE),"") | I47: Calculadora de Escritorio CASIO | J47: 12 dígitos | K47: Medidas: 207,5x159,5x34mm | L47: Solar y a Pila
A48: GX-12B-WE | C48: Calculadoras Casio | D48: =IFERROR(VLOOKUP(A48,'CALC casio'!A:B,2,FALSE),"AGOTADO") -> 35500 | G48: FOTOS1 | H48: =IFERROR(VLOOKUP(A48,EAN!A:C,3,FALSE),"") | I48: Calculadora de Escritorio CASIO | J48: 12 dígitos | K48: Medidas: 207,5x159,5x34mm | L48: Solar y a Pila
A49: HR-100RC | C49: Calculadoras Casio | D49: =IFERROR(VLOOKUP(A49,'CALC casio'!A:B,2,FALSE),"AGOTADO") -> 118500 | G49: FOTOS1 | H49: =IFERROR(VLOOKUP(A49,EAN!A:C,3,FALSE),"") | I49: Calculadora con Impresor CASIO | J49: 12 dígitos - 2 colores - 2.0 líneas por seg. | K49: Medidas: 295x165x64,6mm | L49: Pila o Fuente (No Incluida)
...

Sheet EAN
A1: CODIGO | B1: GTIN | C1: en texto
A2: D-AF6500-B | B2: 7799199015959 | C2: =CONCATENATE("'",TEXT(B2,"0")) -> '7799199015959
A3: D-AF6510-B | B3: 7799199017830 | C3: =CONCATENATE("'",TEXT(B3,"0")) -> '7799199017830
A4: D-AF6510-W | B4: 7799199017830 | C4: =CONCATENATE("'",TEXT(B4,"0")) -> '7799199017830
A5: D-AS100 | B5: 7799199013900 | C5: =CONCATENATE("'",TEXT(B5,"0")) -> '7799199013900
A6: D-AS101 | B6: 7799199013900 | C6: =CONCATENATE("'",TEXT(B6,"0")) -> '7799199013900
A7: D-AS102 | B7: 7799199013924 | C7: =CONCATENATE("'",TEXT(B7,"0")) -> '7799199013924
A8: D-AS200 | B8: 7799199015720 | C8: =CONCATENATE("'",TEXT(B8,"0")) -> '7799199015720
A9: D-AS201 | B9: 7799199015737 | C9: =CONCATENATE("'",TEXT(B9,"0")) -> '7799199015737
A10: D-AS300 | B10: 7799199015744 | C10: =CONCATENATE("'",TEXT(B10,"0")) -> '7799199015744
A11: D-AS400 | B11: 7799199015751 | C11: =CONCATENATE("'",TEXT(B11,"0")) -> '7799199015751
A12: D-AS500 | B12: 7799199015768 | C12: =CONCATENATE("'",TEXT(B12,"0")) -> '7799199015768
A13: D-AU102-WE | B13: 7798019955376 | C13: =CONCATENATE("'",TEXT(B13,"0")) -> '7798019955376
... A16: D-AU315-BK | B16: 7799199014822 | C16: =CONCATENATE("'",TEXT(B16,"0")) -> '7799199014822
A17: D-AU401 | B17: 7798019954652 | C17: =CONCATENATE("'",TEXT(B17,"0")) -> '7798019954652
A18: D-AU402 | B18: 7798019954669 | C18: =CONCATENATE("'",TEXT(B18,"0")) -> '7798019954669
A19: D-AU406-RD | B19: 7798019950838 | C19: =CONCATENATE("'",TEXT(B19,"0")) -> '7798019950838
A20: D-AU512-BK | B20: 7798019955414 | C20: =CONCATENATE("'",TEXT(B20,"0")) -> '7798019955414
A21: D-AU513-BK | B21: 7798019955415 | C21: =CONCATENATE("'",TEXT(B21,"0")) -> '7798019955415
A22: D-AU515-BK | B22: 7798019955417 | C22: =CONCATENATE("'",TEXT(B22,"0")) -> '7798019955417
A23: D-AU516-BK | B23: 7798019955417 | C23: =CONCATENATE("'",TEXT(B23,"0")) -> '7798019955417
A24: D-AU517-BK | B24: 7798019955417 | C24: =CONCATENATE("'",TEXT(B24,"0")) -> '7798019955417
A25: D-AU518-BK | B25: 7798019955417 | C25: =CONCATENATE("'",TEXT(B25,"0")) -> '7798019955417
A26: D-AU519-WE | B26: 7798019955417 | C26: =CONCATENATE("'",TEXT(B26,"0")) -> '7798019955417
A27: D-C120USBP | B27: 7799199014846 | C27: =CONCATENATE("'",TEXT(B27,"0")) -> '7799199014846
A28: D-C120USBR | B28: 7798019955833 | C28: =CONCATENATE("'",TEXT(B28,"0")) -> '7798019955833
A29: D-CF1000 | B29: 7799199017861 | C29: =CONCATENATE("'",TEXT(B29,"0")) -> '7799199017861
A30: D-COR150-B | B30: 7799199016031 | C30: =CONCATENATE("'",TEXT(B30,"0")) -> '7799199016031
... A32: D-ES300-B | B32: 7799199017854 | C32: =CONCATENATE("'",TEXT(B32,"0")) -> '7799199017854
A33: D-GA100 | B33: .7798019951545 | C33: =CONCATENATE("'",TEXT(B33,"0")) -> '.7798019951545
A34: D-MC12 | B34: 7799199016062 | C34: =CONCATENATE("'",TEXT(B34,"0")) -> '7799199016062
A35: D-PI1200-B | B35: 7799199016055 | C35: =CONCATENATE("'",TEXT(B35,"0")) -> '7799199016055
A36: D-PI1200-W | B36: 7799199016055 | C36: =CONCATENATE("'",TEXT(B36,"0")) -> '7799199016055
A37: D-RK1 | B37: 7798019955284 | C37: =CONCATENATE("'",TEXT(B37,"0")) -> '7798019955284
A38: D-RK3 | B38: 7798019955307 | C38: =CONCATENATE("'",TEXT(B38,"0")) -> '7798019955307
A39: D-RK4 | B39: 7798019950647 | C39: =CONCATENATE("'",TEXT(B39,"0")) -> '7798019950647
A40: D-RK7 | B40: 7798019950616 | C40: =CONCATENATE("'",TEXT(B40,"0")) -> '7798019950616
A41: D-RK9 | B41: 7798019950692 | C41: =CONCATENATE("'",TEXT(B41,"0")) -> '7798019950692
A42: D-RP38-BK | B42: 7798019950104 | C42: =CONCATENATE("'",TEXT(B42,"0")) -> '7798019950104
A43: D-RP38-RD | B43: 7798019955871 | C43: =CONCATENATE("'",TEXT(B43,"0")) -> '7798019955871
...

Sheet DAIHATSU
A1: ART_COD | B1: ART_PRE | C1: ART_STK | D1: ART_STKT | E1: PRODUCTOS | H1: NO VENDER | L1: ART_COD | M1: CODCASIO
H2: D-AU303-GD | L2: AX120B | M2: AX-120B
H3: D-AU303-RG | L3: DX12B | M3: DX-12B-BK
H4: D-AU307-BK | L4: DX12B-WE | M4: DX-12B-WE
A5: D-AS100 | B5: 24900 | C5: 252 | D5: 0 | E5: =VLOOKUP(A5,PRODUCTOS!A:A,1,FALSE) -> D-AS100 | H5: D-AU307-GN | L5: FX570ESP2B | M5: FX-570ESPLUS2BU
A6: D-AS101 | B6: 33900 | C6: 482 | E6: =VLOOKUP(A6,PRODUCTOS!A:A,1,FALSE) -> D-AS101 | H6: D-AU307-PK | L6: FX570ESP2P | M6: FX-570ESPLUS2PK
A7: D-AS102 | B7: 38900 | C7: 394 | E7: =VLOOKUP(A7,PRODUCTOS!A:A,1,FALSE) -> D-AS102 | H7: D-AU307-PU | L7: FX570ESPL2 | M7: FX-570ESPLUS2
A8: D-AS200 | B8: 135900 | C8: 866 | E8: =VLOOKUP(A8,PRODUCTOS!A:A,1,FALSE) -> D-AS200 | H8: D-AU308-GN | L8: FX570LAC-W | M8: FX-570LAC-W
A9: D-AS201 | B9: 145900 | C9: 924 | E9: =VLOOKUP(A9,PRODUCTOS!A:A,1,FALSE) -> D-AS201 | H9: D-AU308-PK | L9: FX82ESPL-B | M9: FX-82ESPLUS2-BU
A10: D-AS300 | B10: 57900 | C10: 52 | E10: =VLOOKUP(A10,PRODUCTOS!A:A,1,FALSE) -> D-AS300 | L10: FX82ESPL-P | M10: FX-82ESPLUS2-PK
A11: D-AS400 | B11: 79900 | C11: 636 | E11: =VLOOKUP(A11,PRODUCTOS!A:A,1,FALSE) -> D-AS400 | L11: FX82ESPLU2 | M11: FX-82ESPLUS2
A12: D-AS500 | B12: 89900 | C12: 716 | E12: =VLOOKUP(A12,PRODUCTOS!A:A,1,FALSE) -> D-AS500 | G12: REEMPLAZAR TODOS LOS "/" POR "-" EN ART_COD | L12: FX82LACW-W | M12: FX-82LACW-W
A13: D-AU100-BK | B13: 3900 | C13: 1178 | E13: =VLOOKUP(A13,PRODUCTOS!A:A,1,FALSE) -> D-AU100-BK | L13: FX82LAP2BU | M13: FX-82LAPLUS2-BU
A14: D-AU100-WE | B14: 3900 | C14: 424 | E14: =VLOOKUP(A14,PRODUCTOS!A:A,1,FALSE) -> D-AU100-WE | G14: REEMPLAZAR TODOS LOS "+" POR "-" EN ART_COD | L14: FX82LAP2PK | M14: FX-82LAPLUS2-PK
A15: D-AU102-WE | B15: 10900 | C15: 603 | E15: =VLOOKUP(A15,PRODUCTOS!A:A,1,FALSE) -> D-AU102-WE | L15: FX82MS-2 | M15: FX-82MS-2
A16: D-AU103-BR | B16: 3900 | C16: 11 | E16: =VLOOKUP(A16,PRODUCTOS!A:A,1,FALSE) -> D-AU103-BR | L16: FX95ESPLU2 | M16: FX-95ESPLUS2
A17: D-AU104-BK | B17: 3900 | C17: 345 | E17: =VLOOKUP(A17,PRODUCTOS!A:A,1,FALSE) -> D-AU104-BK | L17: FX95MS-2 | M17: FX-95MS-2
A18: D-AU106-BR | B18: 3900 | C18: 575 | E18: =VLOOKUP(A18,PRODUCTOS!A:A,1,FALSE) -> D-AU106-BR | L18: FX991ESP-B | M18: FX-991ESPLUS2BU
A19: D-AU107-BK | B19: 3900 | C19: 1141 | E19: =VLOOKUP(A19,PRODUCTOS!A:A,1,FALSE) -> D-AU107-BK | L19: FX991ESP-P | M19: FX-991ESPLUS2PK
A20: D-AU315-BK | B20: 26900 | C20: 552 | E20: =VLOOKUP(A20,PRODUCTOS!A:A,1,FALSE) -> D-AU315-BK | L20: FX991ESPL2 | M20: FX-991ESPLUS2
A21: D-AU512-BK | B21: 16500 | C21: 695 | E21: =VLOOKUP(A21,PRODUCTOS!A:A,1,FALSE) -> D-AU512-BK | L21: GX12B | M21: GX-12B-BK
A22: D-AU513-BK | B22: 17500 | C22: 648 | E22: =VLOOKUP(A22,PRODUCTOS!A:A,1,FALSE) -> D-AU513-BK | L22: GX12B-WE | M22: GX-12B-WE
A23: D-AU515-BK | B23: 21500 | C23: 230 | E23: =VLOOKUP(A23,PRODUCTOS!A:A,1,FALSE) -> D-AU515-BK | L23: HR100RC | M23: HR-100RC
A24: D-AU516-BK | B24: 18500 | C24: 184 | E24: =VLOOKUP(A24,PRODUCTOS!A:A,1,FALSE) -> D-AU516-BK | L24: HR150RC | M24: HR-150RC
A25: D-AU518-BK | B25: 21500 | C25: 52 | E25: =VLOOKUP(A25,PRODUCTOS!A:A,1,FALSE) -> D-AU518-BK | L25: HR8RC-BK | M25: HR-8RC-BK
A26: D-AU519-WE | B26: 19500 | C26: 635 | D26: 0 | E26: =VLOOKUP(A26,PRODUCTOS!A:A,1,FALSE) -> D-AU519-WE | L26: HR8RC-WE | M26: HR-8RC-WE
A27: D-BAT-V100 | B27: 208000 | C27: 21 | E27: =VLOOKUP(A27,PRODUCTOS!A:A,1,FALSE) -> D-BAT-V100 | L27: IR-40(B) | M27: IR-40(B)
A28: D-BAT-V101 | B28: 208000 | C28: 50 | E28: =VLOOKUP(A28,PRODUCTOS!A:A,1,FALSE) -> D-BAT-V101 | L28: IR-40(T) | M28: IR-40T(R/B)
A29: D-BAT-V102 | B29: 292000 | C29: 30 | E29: =VLOOKUP(A29,PRODUCTOS!A:A,1,FALSE) -> D-BAT-V102 | L29: LC160LV-BK | M29: LC-160LV-BK
A30: D-BAT-V200 | B30: 585000 | C30: 20 | E30: =VLOOKUP(A30,PRODUCTOS!A:A,1,FALSE) -> D-BAT-V200 | L30: LC160LV-WE | M30: LC-160LV-WE
A31: D-BAT-V300 | B31: 338000 | C31: 20 | E31: =VLOOKUP(A31,PRODUCTOS!A:A,1,FALSE) -> D-BAT-V300 | L31: MS120FM | M31: MS-120FM
A32: D-BAT-V301 | B32: 533000 | C32: 20 | E32: =VLOOKUP(A32,PRODUCTOS!A:A,1,FALSE) -> D-BAT-V301 | L32: MS20UC-LB | M32: MS-20UC-LB
A33: D-CE18-BU | B33: 199900 | C33: 51 | E33: =VLOOKUP(A33,PRODUCTOS!A:A,1,FALSE) -> D-CE18-BU | L33: MS20UC-PK | M33: MS-20UC-PK
A34: D-CF2000 | B34: 189900 | C34: 362 | E34: =VLOOKUP(A34,PRODUCTOS!A:A,1,FALSE) -> D-CF2000 | L34: MS20UC-RD | M34: MS-20UC-RD
A35: D-CF3000 | B35: 429900 | C35: 475 | E35: =VLOOKUP(A35,PRODUCTOS!A:A,1,FALSE) -> D-CF3000 | L35: MS20UC-WE | M35: MS-20UC-WE
A36: D-CF4000-B | B36: 136900 | C36: 760 | E36: =VLOOKUP(A36,PRODUCTOS!A:A,1,FALSE) -> D-CF4000-B | L36: MW8V-BK | M36: MW-8V-BK
A37: D-CF4000-W | B37: 136900 | C37: 769 | E37: =VLOOKUP(A37,PRODUCTOS!A:A,1,FALSE) -> D-CF4000-W
A38: D-COR150-B | B38: 111900 | C38: 790 | E38: =VLOOKUP(A38,PRODUCTOS!A:A,1,FALSE) -> D-COR150-B
A39: D-COR150-S | B39: 111900 | C39: 791 | E39: =VLOOKUP(A39,PRODUCTOS!A:A,1,FALSE) -> D-COR150-S
A40: D-ES300-B | B40: 54900 | C40: 537 | E40: =VLOOKUP(A40,PRODUCTOS!A:A,1,FALSE) -> D-ES300-B
...

Sheet ML
A1: ART_COD | B1: ART_PRE | C1: ART_STK | D1: ART_STKT | E1: PRODUCTOS | H1: NO VENDER | L1: ART_COD | M1: CODCASIO
A2: ML-ARM01B | B2: 42900 | C2: 169 | E2: =VLOOKUP(A2,PRODUCTOS!A:A,1,FALSE) -> ML-ARM01B | H2: D-AU303-GD | L2: AX120B | M2: AX-120B
A3: ML-ARM01G | B3: 42900 | C3: 91 | E3: =VLOOKUP(A3,PRODUCTOS!A:A,1,FALSE) -> ML-ARM01G | H3: D-AU303-RG | L3: DX12B | M3: DX-12B-BK
A4: ML-ARM03G | B4: 24900 | C4: 21 | D4: 0 | E4: =VLOOKUP(A4,PRODUCTOS!A:A,1,FALSE) -> ML-ARM03G | H4: D-AU307-BK | L4: DX12B-WE | M4: DX-12B-WE
A5: ML-ARM04G | B5: 38900 | C5: 81 | E5: =VLOOKUP(A5,PRODUCTOS!A:A,1,FALSE) -> ML-ARM04G | H5: D-AU307-GN | L5: FX570ESP2B | M5: FX-570ESPLUS2BU
A6: ML-ARM05G | B6: 38900 | C6: 75 | E6: =VLOOKUP(A6,PRODUCTOS!A:A,1,FALSE) -> ML-ARM05G | H6: D-AU307-PK | L6: FX570ESP2P | M6: FX-570ESPLUS2PK
A7: ML-ARM06B | B7: 39900 | C7: 92 | E7: =VLOOKUP(A7,PRODUCTOS!A:A,1,FALSE) -> ML-ARM06B | H7: D-AU307-PU | L7: FX570ESPL2 | M7: FX-570ESPLUS2
A8: ML-ARM06W | B8: 39900 | C8: 93 | E8: =VLOOKUP(A8,PRODUCTOS!A:A,1,FALSE) -> ML-ARM06W | H8: D-AU308-GN | L8: FX570LAC-W | M8: FX-570LAC-W
A9: ML-ARM07B | B9: 38900 | C9: 86 | E9: =VLOOKUP(A9,PRODUCTOS!A:A,1,FALSE) -> ML-ARM07B | H9: D-AU308-PK | L9: FX82ESPL-B | M9: FX-82ESPLUS2-BU
A10: ML-ARM07W | B10: 38900 | C10: 36 | E10: =VLOOKUP(A10,PRODUCTOS!A:A,1,FALSE) -> ML-ARM07W | L10: FX82ESPL-P | M10: FX-82ESPLUS2-PK
A11: ML-ARM08W | B11: 48900 | C11: 52 | E11: =VLOOKUP(A11,PRODUCTOS!A:A,1,FALSE) -> ML-ARM08W | L11: FX82ESPLU2 | M11: FX-82ESPLUS2
A12: ML-ARM09B | B12: 35900 | C12: 85 | E12: =VLOOKUP(A12,PRODUCTOS!A:A,1,FALSE) -> ML-ARM09B | G12: REEMPLAZAR TODOS LOS "/" POR "-" EN ART_COD | L12: FX82LACW-W | M12: FX-82LACW-W
A13: ML-ARM09W | B13: 35900 | C13: 107 | E13: =VLOOKUP(A13,PRODUCTOS!A:A,1,FALSE) -> ML-ARM09W | L13: FX82LAP2BU | M13: FX-82LAPLUS2-BU
A14: ML-BA-T3X2 | B14: 27900 | C14: 36 | E14: =VLOOKUP(A14,PRODUCTOS!A:A,1,FALSE) -> ML-BA-T3X2 | G14: REEMPLAZAR TODOS LOS "+" POR "-" EN ART_COD | L14: FX82LAP2PK | M14: FX-82LAPLUS2-PK
A15: ML-BA888X1 | B15: 19900 | C15: 0 | D15: 638 | E15: =VLOOKUP(A15,PRODUCTOS!A:A,1,FALSE) -> ML-BA888X1 | L15: FX82MS-2 | M15: FX-82MS-2
A16: ML-BA888X2 | B16: 38900 | C16: 0 | D16: 2028 | E16: =VLOOKUP(A16,PRODUCTOS!A:A,1,FALSE) -> ML-BA888X2 | L16: FX95ESPLU2 | M16: FX-95ESPLUS2
A17: ML-BAA58S | B17: 79900 | C17: 57 | E17: =VLOOKUP(A17,PRODUCTOS!A:A,1,FALSE) -> ML-BAA58S | L17: FX991ESP-B | M17: FX-991ESPLUS2BU
A18: ML-BAK5PLU | B18: 129900 | C18: 137 | E18: =VLOOKUP(A18,PRODUCTOS!A:A,1,FALSE) -> ML-BAK5PLU | L18: FX991ESP-P | M18: FX-991ESPLUS2PK
A19: ML-BAK6 | B19: 84900 | C19: 35 | E19: =VLOOKUP(A19,PRODUCTOS!A:A,1,FALSE) -> ML-BAK6 | L19: FX991ESPL2 | M19: FX-991ESPLUS2
A20: ML-BASE01B | B20: 24900 | C20: 81 | E20: =VLOOKUP(A20,PRODUCTOS!A:A,1,FALSE) -> ML-BASE01B | L20: HR100RC | M20: HR-100RC
A21: ML-BASE02G | B21: 39900 | C21: 125 | D21: 0 | E21: =VLOOKUP(A21,PRODUCTOS!A:A,1,FALSE) -> ML-BASE02G | L21: HR150RC | M21: HR-150RC
A22: ML-BAT888S | B22: 4500 | D22: 114 | E22: =VLOOKUP(A22,PRODUCTOS!A:A,1,FALSE) -> ML-BAT888S | L22: HR8RC-BK | M22: HR-8RC-BK
A23: ML-BAUV17L | B23: 114900 | C23: 135 | E23: =VLOOKUP(A23,PRODUCTOS!A:A,1,FALSE) -> ML-BAUV17L | L23: HR8RC-WE | M23: HR-8RC-WE
A24: ML-BAUV5R5 | B24: 79900 | C24: 379 | D24: 0 | E24: =VLOOKUP(A24,PRODUCTOS!A:A,1,FALSE) -> ML-BAUV5R5 | L24: IR-40(B) | M24: IR-40(B)
A25: ML-BAUV822 | B25: 97900 | C25: 11 | E25: =VLOOKUP(A25,PRODUCTOS!A:A,1,FALSE) -> ML-BAUV822 | L25: IR-40(T) | M25: IR-40T(R/B)
A26: ML-BEACH | B26: 25900 | C26: 105 | E26: =VLOOKUP(A26,PRODUCTOS!A:A,1,FALSE) -> ML-BEACH | L26: LC160LV-BK | M26: LC-160LV-BK
A27: ML-BEACH2 | B27: 25900 | C27: 175 | E27: =VLOOKUP(A27,PRODUCTOS!A:A,1,FALSE) -> ML-BEACH2 | L27: LC160LV-WE | M27: LC-160LV-WE
A28: ML-BOLSA2N | B28: 59900 | C28: 298 | E28: =VLOOKUP(A28,PRODUCTOS!A:A,1,FALSE) -> ML-BOLSA2N | L28: MS120FM | M28: MS-120FM
A29: ML-BOLSO-N | B29: 26900 | C29: 24 | E29: =VLOOKUP(A29,PRODUCTOS!A:A,1,FALSE) -> ML-BOLSO-N | L29: MS20UC-LB | M29: MS-20UC-LB
A30: ML-CARRO01 | B30: 69900 | C30: 51 | E30: =VLOOKUP(A30,PRODUCTOS!A:A,1,FALSE) -> ML-CARRO01 | L30: MS20UC-PK | M30: MS-20UC-PK
A31: ML-CARRO02 | B31: 109900 | C31: 199 | E31: =VLOOKUP(A31,PRODUCTOS!A:A,1,FALSE) -> ML-CARRO02 | L31: MS20UC-RD | M31: MS-20UC-RD
A32: ML-CARRO03 | B32: 69900 | C32: 300 | E32: =VLOOKUP(A32,PRODUCTOS!A:A,1,FALSE) -> ML-CARRO03 | L32: MS20UC-WE | M32: MS-20UC-WE
A33: ML-DIREC-A | B33: 22900 | C33: 109 | E33: =VLOOKUP(A33,PRODUCTOS!A:A,1,FALSE) -> ML-DIREC-A | L33: MW8V-BK | M33: MW-8V-BK
A34: ML-DIREC-M | B34: 22900 | C34: 408 | E34: =VLOOKUP(A34,PRODUCTOS!A:A,1,FALSE) -> ML-DIREC-M | L34: MW8V-WE | M34: MW-8V-WE
A35: ML-DIREC-R | B35: 22900 | C35: 200 | E35: =VLOOKUP(A35,PRODUCTOS!A:A,1,FALSE) -> ML-DIREC-R | L35: MX120B | M35: MX-120B
A36: ML-DIREC-V | B36: 22900 | C36: 39 | E36: =VLOOKUP(A36,PRODUCTOS!A:A,1,FALSE) -> ML-DIREC-V | L36: MX12B-GNRD | M36: MX-12B-GNRD
A37: ML-GAZ01-A | B37: 224900 | C37: 46 | E37: =VLOOKUP(A37,PRODUCTOS!A:A,1,FALSE) -> ML-GAZ01-A | L37: MX12B-PKLB | M37: MX-12B-PKLB
A38: ML-GAZ01-R | B38: 224900 | C38: 212 | D38: 0 | E38: =VLOOKUP(A38,PRODUCTOS!A:A,1,FALSE) -> ML-GAZ01-R | L38: MX12B-WE | M38: MX-12B-WE
A39: ML-GAZ01-W | B39: 224900 | C39: 83 | E39: =VLOOKUP(A39,PRODUCTOS!A:A,1,FALSE) -> ML-GAZ01-W | L39: XR-18WE1 | M39: XR-18WE1
A40: ML-GAZ02-A | B40: 169900 | C40: 433 | E40: =VLOOKUP(A40,PRODUCTOS!A:A,1,FALSE) -> ML-GAZ02-A | L40: XR-9WE1 | M40: XR-9WE1
...

Sheet CALC casio
A1: ART_COD | B1: ART_PRE | C1: ART_STK | D1: ART_STKT | E1: PRODUCTOS | H1: NO VENDER | L1: ART_COD | M1: CODCASIO
A2: AX-120B | B2: 27500 | C2: 52 | E2: =VLOOKUP(A2,PRODUCTOS!A:A,1,FALSE) -> AX-120B | H2: D-AU303-GD | L2: AX120B | M2: AX-120B
A3: AX-120ST | B3: 36500 | C3: 12 | E3: =VLOOKUP(A3,PRODUCTOS!A:A,1,FALSE) -> AX-120ST | H3: D-AU303-RG | L3: DX12B | M3: DX-12B-BK
A4: DX-120B | B4: 33500 | C4: 2 | E4: =VLOOKUP(A4,PRODUCTOS!A:A,1,FALSE) -> DX-120B | H4: D-AU307-BK | L4: DX12B-WE | M4: DX-12B-WE
A5: DX-120B | B5: 33900 | C5: 40 | E5: =VLOOKUP(A5,PRODUCTOS!A:A,1,FALSE) -> DX-120B | H5: D-AU307-GN | L5: FX570ESP2B | M5: FX-570ESPLUS2BU
A6: DX-12B-BK | B6: 30900 | C6: 46 | E6: =VLOOKUP(A6,PRODUCTOS!A:A,1,FALSE) -> DX-12B-BK | H6: D-AU307-PK | L6: FX570ESP2P | M6: FX-570ESPLUS2PK
A7: DX-12B-WE | B7: 30900 | C7: 41 | E7: =VLOOKUP(A7,PRODUCTOS!A:A,1,FALSE) -> #N/A | H7: D-AU307-PU | L7: FX570ESPL2 | M7: FX-570ESPLUS2
A8: FX-570ESPLUS2BU | B8: 61900 | C8: 112 | E8: =VLOOKUP(A8,PRODUCTOS!A:A,1,FALSE) -> FX-570ESPLUS2BU | H8: D-AU308-GN | L8: FX570LAC-W | M8: FX-570LAC-W
A9: FX-570ESPLUS2PK | B9: 61900 | C9: 81 | E9: =VLOOKUP(A9,PRODUCTOS!A:A,1,FALSE) -> FX-570ESPLUS2PK | H9: D-AU308-PK | L9: FX82ESPL-B | M9: FX-82ESPLUS2-BU
A10: FX-570ESPLUS2 | B10: 61900 | C10: 201 | E10: =VLOOKUP(A10,PRODUCTOS!A:A,1,FALSE) -> FX-570ESPLUS2 | L10: FX82ESPL-P | M10: FX-82ESPLUS2-PK
A11: FX-570LAC-W | B11: 79500 | C11: 40 | E11: =VLOOKUP(A11,PRODUCTOS!A:A,1,FALSE) -> FX-570LAC-W | L11: FX82ESPLU2 | M11: FX-82ESPLUS2
A12: FX-570LAPLUS2 | B12: 61900 | C12: 200 | E12: =VLOOKUP(A12,PRODUCTOS!A:A,1,FALSE) -> #N/A | G12: REEMPLAZAR TODOS LOS "/" POR "-" EN ART_COD | L12: FX82LACW-W | M12: FX-82LACW-W
A13: FX-570MS-2 | B13: 56500 | C13: 40 | E13: =VLOOKUP(A13,PRODUCTOS!A:A,1,FALSE) -> #N/A | L13: FX82LAP2BU | M13: FX-82LAPLUS2-BU
A14: FX-82ESPLUS2-BU | B14: 37900 | C14: 80 | E14: =VLOOKUP(A14,PRODUCTOS!A:A,1,FALSE) -> FX-82ESPLUS2-BU | G14: REEMPLAZAR TODOS LOS "+" POR "-" EN ART_COD | L14: FX82LAP2PK | M14: FX-82LAPLUS2-PK
A15: FX-82ESPLUS2-PK | B15: 37900 | C15: 80 | E15: =VLOOKUP(A15,PRODUCTOS!A:A,1,FALSE) -> FX-82ESPLUS2-PK | L15: FX82MS-2 | M15: FX-82MS-2
A16: FX-82ESPLUS2 | B16: 37900 | C16: 120 | E16: =VLOOKUP(A16,PRODUCTOS!A:A,1,FALSE) -> FX-82ESPLUS2 | L16: FX95ESPLU2 | M16: FX-95ESPLUS2
A17: FX-82LACW-W | B17: 47500 | C17: 119 | E17: =VLOOKUP(A17,PRODUCTOS!A:A,1,FALSE) -> FX-82LACW-W | L17: FX95MS-2 | M17: FX-95MS-2
A18: FX-82LAPLUS2-BK | B18: 37900 | C18: 80 | E18: =VLOOKUP(A18,PRODUCTOS!A:A,1,FALSE) -> FX-82LAPLUS2-BK | L18: FX991ESP-B | M18: FX-991ESPLUS2BU
A19: FX-82LAPLUS2-BU | B19: 37900 | C19: 98 | E19: =VLOOKUP(A19,PRODUCTOS!A:A,1,FALSE) -> FX-82LAPLUS2-BU | L19: FX991ESP-P | M19: FX-991ESPLUS2PK
A20: FX-82LAPLUS2-PK | B20: 37900 | C20: 22 | D20: 0 | E20: =VLOOKUP(A20,PRODUCTOS!A:A,1,FALSE) -> FX-82LAPLUS2-PK | L20: FX991ESPL2 | M20: FX-991ESPLUS2
A21: FX-82MS-2 | B21: 32500 | C21: 527 | D21: 0 | E21: =VLOOKUP(A21,PRODUCTOS!A:A,1,FALSE) -> FX-82MS-2 | L21: GX12B | M21: GX-12B-BK
A22: FX-82MS-2-PK | B22: 32500 | C22: 80 | E22: =VLOOKUP(A22,PRODUCTOS!A:A,1,FALSE) -> #N/A | L22: GX12B-WE | M22: GX-12B-WE
A23: FX-95ESPLUS2 | B23: 45500 | C23: 196 | E23: =VLOOKUP(A23,PRODUCTOS!A:A,1,FALSE) -> FX-95ESPLUS2 | L23: HR100RC | M23: HR-100RC
A24: FX-95MS-2 | B24: 42500 | C24: 304 | E24: =VLOOKUP(A24,PRODUCTOS!A:A,1,FALSE) -> FX-95MS-2 | L24: HR150RC | M24: HR-150RC
A25: FX-991ESPLUS2BU | B25: 69900 | C25: 119 | E25: =VLOOKUP(A25,PRODUCTOS!A:A,1,FALSE) -> FX-991ESPLUS2BU | L25: HR8RC-BK | M25: HR-8RC-BK
A26: FX-991ESPLUS2PK | B26: 69900 | C26: 116 | E26: =VLOOKUP(A26,PRODUCTOS!A:A,1,FALSE) -> FX-991ESPLUS2PK | L26: HR8RC-WE | M26: HR-8RC-WE
A27: FX-991ESPLUS2 | B27: 69900 | C27: 242 | E27: =VLOOKUP(A27,PRODUCTOS!A:A,1,FALSE) -> FX-991ESPLUS2 | L27: IR-40(B) | M27: IR-40(B)
A28: FX-991LACW | B28: 88500 | C28: 122 | D28: 0 | E28: =VLOOKUP(A28,PRODUCTOS!A:A,1,FALSE) -> FX-991LACW | L28: IR-40(T) | M28: IR-40T(R/B)
A29: FX-991LAPLUS2 | B29: 69900 | C29: 138 | E29: =VLOOKUP(A29,PRODUCTOS!A:A,1,FALSE) -> FX-991LAPLUS2 | L29: LC160LV-BK | M29: LC-160LV-BK
A30: GX-12B-BK | B30: 35500 | C30: 6 | E30: =VLOOKUP(A30,PRODUCTOS!A:A,1,FALSE) -> GX-12B-BK | L30: LC160LV-WE | M30: LC-160LV-WE
A31: GX-12B-WE | B31: 35500 | C31: 30 | E31: =VLOOKUP(A31,PRODUCTOS!A:A,1,FALSE) -> GX-12B-WE | L31: MS120FM | M31: MS-120FM
A32: HR-100RC | B32: 118500 | C32: 40 | E32: =VLOOKUP(A32,PRODUCTOS!A:A,1,FALSE) -> HR-100RC | L32: MS20UC-LB | M32: MS-20UC-LB
A33: HR-150RC | B33: 148500 | C33: 14 | E33: =VLOOKUP(A33,PRODUCTOS!A:A,1,FALSE) -> HR-150RC | L33: MS20UC-PK | M33: MS-20UC-PK
A34: HR-8RC-WE | B34: 86500 | C34: 25 | E34: =VLOOKUP(A34,PRODUCTOS!A:A,1,FALSE) -> HR-8RC-WE
A35: LC-160LV-BK | B35: 7500 | C35: 289 | E35: =VLOOKUP(A35,PRODUCTOS!A:A,1,FALSE) -> LC-160LV-BK
A36: LC-160LV-WE | B36: 7500 | C36: 88 | E36: =VLOOKUP(A36,PRODUCTOS!A:A,1,FALSE) -> LC-160LV-WE
A37: MS-20UC-BU | B37: 25500 | C37: 20 | E37: =VLOOKUP(A37,PRODUCTOS!A:A,1,FALSE) -> MS-20UC-BU | L37: MX12B-GNRD | M37: MX-12B-GNRD
A38: MS-20UC-GN | B38: 25500 | C38: 20 | E38: =VLOOKUP(A38,PRODUCTOS!A:A,1,FALSE) -> MS-20UC-GN | L38: MX12B-PKLB | M38: MX-12B-PKLB
A39: MS-20UC-LB | B39: 25500 | C39: 12 | E39: =VLOOKUP(A39,PRODUCTOS!A:A,1,FALSE) -> MS-20UC-LB | L39: MX12B-WE | M39: MX-12B-WE
A40: MS-20UC-PK | B40: 25500 | C40: 4 | E40: =VLOOKUP(A40,PRODUCTOS!A:A,1,FALSE) -> MS-20UC-PK | L40: XR-18WE1 | M40: XR-18WE1
...

Sheet CALC daihatsu
A1: ART_COD | B1: ART_PRE | C1: ART_STK | D1: ART_STKT | E1: PRODUCTOS | H1: NO VENDER | L1: ART_COD | M1: CODCASIO
A2: D-CB100 | B2: 71900 | C2: 2135 | D2: 0 | E2: =VLOOKUP(A2,PRODUCTOS!A:A,1,FALSE) -> D-CB100 | H2: D-AU303-GD | L2: AX120B | M2: AX-120B
A3: D-CB2000 | B3: 119900 | C3: 398 | E3: =VLOOKUP(A3,PRODUCTOS!A:A,1,FALSE) -> D-CB2000 | H3: D-AU303-RG | L3: DX12B | M3: DX-12B-BK
A4: D-CB210 | B4: 89900 | C4: 1029 | E4: =VLOOKUP(A4,PRODUCTOS!A:A,1,FALSE) -> D-CB210 | H4: D-AU307-BK | L4: DX12B-WE | M4: DX-12B-WE
A5: D-CB3000-C | B5: 759900 | C5: 34 | E5: =VLOOKUP(A5,PRODUCTOS!A:A,1,FALSE) -> D-CB3000-C | H5: D-AU307-GN | L5: FX570ESP2B | M5: FX-570ESPLUS2BU
A6: D-CB40 | B6: 35900 | C6: 2323 | E6: =VLOOKUP(A6,PRODUCTOS!A:A,1,FALSE) -> D-CB40 | H6: D-AU307-PK | L6: FX570ESP2P | M6: FX-570ESPLUS2PK
A7: D-E1200T | B7: 15900 | C7: 186 | E7: =VLOOKUP(A7,PRODUCTOS!A:A,1,FALSE) -> D-E1200T | H7: D-AU307-PU | L7: FX570ESPL2 | M7: FX-570ESPLUS2
A8: D-E1205 | B8: 15900 | C8: 279 | D8: 0 | E8: =VLOOKUP(A8,PRODUCTOS!A:A,1,FALSE) -> D-E1205 | H8: D-AU308-GN | L8: FX570LAC-W | M8: FX-570LAC-W
A9: D-E1240-B | B9: 16900 | C9: 235 | D9: 30 | E9: =VLOOKUP(A9,PRODUCTOS!A:A,1,FALSE) -> D-E1240-B | H9: D-AU308-PK | L9: FX82ESPL-B | M9: FX-82ESPLUS2-BU
A10: D-E1240-W | B10: 16900 | C10: 177 | D10: 0 | E10: =VLOOKUP(A10,PRODUCTOS!A:A,1,FALSE) -> D-E1240-W | L10: FX82ESPL-P | M10: FX-82ESPLUS2-PK
A11: D-E1275-BK | B11: 13900 | C11: 364 | E11: =VLOOKUP(A11,PRODUCTOS!A:A,1,FALSE) -> D-E1275-BK | L11: FX82ESPLU2 | M11: FX-82ESPLUS2
A12: D-E1275-WE | B12: 13900 | C12: 78 | E12: =VLOOKUP(A12,PRODUCTOS!A:A,1,FALSE) -> D-E1275-WE | G12: REEMPLAZAR TODOS LOS "/" POR "-" EN ART_COD | L12: FX82LACW-W | M12: FX-82LACW-W
A13: D-E1280-BK | B13: 13900 | C13: 526 | E13: =VLOOKUP(A13,PRODUCTOS!A:A,1,FALSE) -> D-E1280-BK | L13: FX82LAP2BU | M13: FX-82LAPLUS2-BU
A14: D-E1280-WE | B14: 13900 | C14: 207 | E14: =VLOOKUP(A14,PRODUCTOS!A:A,1,FALSE) -> D-E1280-WE | G14: REEMPLAZAR TODOS LOS "+" POR "-" EN ART_COD | L14: FX82LAP2PK | M14: FX-82LAPLUS2-PK
A15: D-E1285-BK | B15: 16900 | C15: 638 | E15: =VLOOKUP(A15,PRODUCTOS!A:A,1,FALSE) -> D-E1285-BK | L15: FX82MS-2 | M15: FX-82MS-2
A16: D-E1285-WE | B16: 16900 | C16: 245 | E16: =VLOOKUP(A16,PRODUCTOS!A:A,1,FALSE) -> D-E1285-WE | L16: FX95ESPLU2 | M16: FX-95ESPLUS2
A17: D-I100T-BK | B17: 104900 | C17: 603 | E17: =VLOOKUP(A17,PRODUCTOS!A:A,1,FALSE) -> D-I100T-BK | L17: FX95MS-2 | M17: FX-95MS-2
A18: D-I100T-WE | B18: 104900 | C18: 448 | D18: 0 | E18: =VLOOKUP(A18,PRODUCTOS!A:A,1,FALSE) -> D-I100T-WE | L18: FX991ESP-B | M18: FX-991ESPLUS2BU
A19: D-I200TH-B | B19: 139900 | C19: 250 | E19: =VLOOKUP(A19,PRODUCTOS!A:A,1,FALSE) -> D-I200TH-B | L19: FX991ESP-P | M19: FX-991ESPLUS2PK
A20: D-I200TH-W | B20: 139900 | C20: 394 | E20: =VLOOKUP(A20,PRODUCTOS!A:A,1,FALSE) -> D-I200TH-W | L20: FX991ESPL2 | M20: FX-991ESPLUS2
A21: D-I8T-BK | B21: 74900 | C21: 282 | D21: 4 | E21: =VLOOKUP(A21,PRODUCTOS!A:A,1,FALSE) -> D-I8T-BK | L21: GX12B | M21: GX-12B-BK
A22: D-I8T-WE | B22: 74900 | C22: 72 | D22: 91 | E22: =VLOOKUP(A22,PRODUCTOS!A:A,1,FALSE) -> D-I8T-WE | L22: GX12B-WE | M22: GX-12B-WE
A23: D-P1013B | B23: 8900 | C23: 129 | E23: =VLOOKUP(A23,PRODUCTOS!A:A,1,FALSE) -> D-P1013B | L23: HR100RC | M23: HR-100RC
A24: D-P1013W | B24: 8900 | C24: 349 | E24: =VLOOKUP(A24,PRODUCTOS!A:A,1,FALSE) -> D-P1013W | L24: HR150RC | M24: HR-150RC
A25: D-P803 | B25: 5900 | C25: 482 | D25: 628 | E25: =VLOOKUP(A25,PRODUCTOS!A:A,1,FALSE) -> D-P803 | L25: HR8RC-BK | M25: HR-8RC-BK
A26: D-P803S | B26: 6900 | C26: 377 | D26: 588 | E26: =VLOOKUP(A26,PRODUCTOS!A:A,1,FALSE) -> D-P803S | L26: HR8RC-WE | M26: HR-8RC-WE
A27: D-X570LAPLUS | B27: 36900 | C27: 429 | D27: 73 | E27: =VLOOKUP(A27,PRODUCTOS!A:A,1,FALSE) -> D-X570LAPLUS | L27: IR-40(B) | M27: IR-40(B)
A28: D-X82 | B28: 16900 | C28: 1000 | E28: =VLOOKUP(A28,PRODUCTOS!A:A,1,FALSE) -> D-X82 | L28: LC160LV-WE | M28: LC-160LV-WE
A29: D-X95 | B29: 19900 | C29: 1000 | E29: =VLOOKUP(A29,PRODUCTOS!A:A,1,FALSE) -> D-X95 | L29: MS20UC-LB | M29: MS-20UC-LB
L30: MS20UC-PK | M30: MS-20UC-PK
L31: MS20UC-RD | M31: MS-20UC-RD
L32: MS20UC-WE | M32: MS-20UC-WE
L33: MW8V-BK | M33: MW-8V-BK
L34: MW8V-WE | M34: MW-8V-WE
L35: MX120B | M35: MX-120B
L36: MX12B-GNRD | M36: MX-12B-GNRD
L37: MX12B-PKLB | M37: MX-12B-PKLB
L38: MX12B-WE | M38: MX-12B-WE
L39: XR-18WE1 | M39: XR-18WE1
L40: XR-9WE1 | M40: XR-9WE1
...

Sheet STKAUX (sistema)
A1: ART_COD | B1: ART_PRE | C1: ART_STK | D1: ART_STKT | E1: PRODUCTOS | H1: NO VENDER | L1: ART_COD | M1: CODCASIO
A2: D-AF6500-B | B2: 87900 | C2: 876 | E2: =VLOOKUP(A2,PRODUCTOS!A:A,1,FALSE) -> D-AF6500-B | H2: D-AU303-GD | L2: AX120B | M2: AX-120B
A3: D-AF6510-B | B3: 79900 | C3: 874 | E3: =VLOOKUP(A3,PRODUCTOS!A:A,1,FALSE) -> D-AF6510-B | H3: D-AU303-RG | L3: DX12B | M3: DX-12B-BK
A4: D-AF6510-W | B4: 79900 | C4: 892 | E4: =VLOOKUP(A4,PRODUCTOS!A:A,1,FALSE) -> D-AF6510-W | H4: D-AU307-BK | L4: DX12B-WE | M4: DX-12B-WE
A5: D-AS100 | B5: 21900 | C5: 803 | D5: 0 | E5: =VLOOKUP(A5,PRODUCTOS!A:A,1,FALSE) -> D-AS100 | H5: D-AU307-GN | L5: FX570ESP2B | M5: FX-570ESPLUS2BU
A6: D-AS101 | B6: 30900 | C6: 857 | E6: =VLOOKUP(A6,PRODUCTOS!A:A,1,FALSE) -> D-AS101 | H6: D-AU307-PK | L6: FX570ESP2P | M6: FX-570ESPLUS2PK
A7: D-AS102 | B7: 33900 | C7: 636 | E7: =VLOOKUP(A7,PRODUCTOS!A:A,1,FALSE) -> D-AS102 | H7: D-AU307-PU | L7: FX570ESPL2 | M7: FX-570ESPLUS2
A8: D-AS200 | B8: 135900 | C8: 922 | E8: =VLOOKUP(A8,PRODUCTOS!A:A,1,FALSE) -> D-AS200 | H8: D-AU308-GN | L8: FX570LAC-W | M8: FX-570LAC-W
A9: D-AS201 | B9: 145900 | C9: 966 | E9: =VLOOKUP(A9,PRODUCTOS!A:A,1,FALSE) -> D-AS201 | H9: D-AU308-PK | L9: FX82ESPL-B | M9: FX-82ESPLUS2-BU
A10: D-AS300 | B10: 57900 | C10: 951 | E10: =VLOOKUP(A10,PRODUCTOS!A:A,1,FALSE) -> D-AS300 | L10: FX82ESPL-P | M10: FX-82ESPLUS2-PK
A11: D-AS400 | B11: 74900 | C11: 832 | E11: =VLOOKUP(A11,PRODUCTOS!A:A,1,FALSE) -> D-AS400 | L11: FX82ESPLU2 | M11: FX-82ESPLUS2
A12: D-AS500 | B12: 89900 | C12: 844 | E12: =VLOOKUP(A12,PRODUCTOS!A:A,1,FALSE) -> D-AS500 | G12: REEMPLAZAR TODOS LOS "/" POR "-" EN ART_COD | L12: FX82LACW-W | M12: FX-82LACW-W
A13: D-AU100-BK | B13: 3700 | C13: 1641 | E13: =VLOOKUP(A13,PRODUCTOS!A:A,1,FALSE) -> D-AU100-BK | L13: FX82LAP2BU | M13: FX-82LAPLUS2-BU
A14: D-AU100-WE | B14: 3700 | C14: 668 | E14: =VLOOKUP(A14,PRODUCTOS!A:A,1,FALSE) -> D-AU100-WE | G14: REEMPLAZAR TODOS LOS "+" POR "-" EN ART_COD | L14: FX82LAP2PK | M14: FX-82LAPLUS2-PK
A15: D-AU102-WE | B15: 9900 | C15: 701 | E15: =VLOOKUP(A15,PRODUCTOS!A:A,1,FALSE) -> D-AU102-WE | L15: FX82MS-2 | M15: FX-82MS-2
A16: D-AU103-BR | B16: 3700 | C16: 232 | E16: =VLOOKUP(A16,PRODUCTOS!A:A,1,FALSE) -> D-AU103-BR | L16: FX95ESPLU2 | M16: FX-95ESPLUS2
A17: D-AU104-BK | B17: 3700 | C17: 530 | E17: =VLOOKUP(A17,PRODUCTOS!A:A,1,FALSE) -> D-AU104-BK | L17: FX95MS-2 | M17: FX-95MS-2
A18: D-AU106-BR | B18: 3700 | C18: 681 | E18: =VLOOKUP(A18,PRODUCTOS!A:A,1,FALSE) -> D-AU106-BR | L18: FX991ESP-B | M18: FX-991ESPLUS2BU
A19: D-AU107-BK | B19: 3700 | C19: 1302 | E19: =VLOOKUP(A19,PRODUCTOS!A:A,1,FALSE) -> D-AU107-BK | L19: FX991ESP-P | M19: FX-991ESPLUS2PK
A20: D-AU310-BK | B20: 21900 | C20: 825 | E20: =VLOOKUP(A20,PRODUCTOS!A:A,1,FALSE) -> #N/A | L20: FX991ESPL2 | M20: FX-991ESPLUS2
A21: D-AU315-BK | B21: 25500 | C21: 838 | E21: =VLOOKUP(A21,PRODUCTOS!A:A,1,FALSE) -> D-AU315-BK | L21: GX12B | M21: GX-12B-BK
A22: D-AU401 | B22: 22900 | C22: 56 | E22: =VLOOKUP(A22,PRODUCTOS!A:A,1,FALSE) -> #N/A | L22: GX12B-WE | M22: GX-12B-WE
A23: D-AU402 | B23: 15900 | C23: 262 | E23: =VLOOKUP(A23,PRODUCTOS!A:A,1,FALSE) -> #N/A | L23: HR100RC | M23: HR-100RC
A24: D-AU512-BK | B24: 14900 | C24: 786 | E24: =VLOOKUP(A24,PRODUCTOS!A:A,1,FALSE) -> D-AU512-BK | L24: HR150RC | M24: HR-150RC
A25: D-AU513-BK | B25: 15900 | C25: 711 | E25: =VLOOKUP(A25,PRODUCTOS!A:A,1,FALSE) -> D-AU513-BK | L25: HR8RC-BK | M25: HR-8RC-BK
A26: D-AU515-BK | B26: 19900 | C26: 274 | E26: =VLOOKUP(A26,PRODUCTOS!A:A,1,FALSE) -> D-AU515-BK | L26: HR8RC-WE | M26: HR-8RC-WE
... A29: D-AU518-BK | B29: 19900 | C29: 229 | E29: =VLOOKUP(A29,PRODUCTOS!A:A,1,FALSE) -> D-AU518-BK | L29: LC160LV-BK | M29: LC-160LV-BK
A30: D-AU519-WE | B30: 17900 | C30: 690 | D30: 0 | E30: =VLOOKUP(A30,PRODUCTOS!A:A,1,FALSE) -> D-AU519-WE | L30: LC160LV-WE | M30: LC-160LV-WE
A31: D-BAT-V100 | B31: 208000 | C31: 50 | E31: =VLOOKUP(A31,PRODUCTOS!A:A,1,FALSE) -> D-BAT-V100 | L31: MS120FM | M31: MS-120FM
A32: D-BAT-V101 | B32: 208000 | C32: 50 | E32: =VLOOKUP(A32,PRODUCTOS!A:A,1,FALSE) -> D-BAT-V101 | L32: MS20UC-LB | M32: MS-20UC-LB
A33: D-BAT-V102 | B33: 292000 | C33: 30 | E33: =VLOOKUP(A33,PRODUCTOS!A:A,1,FALSE) -> D-BAT-V102 | L33: MS20UC-PK | M33: MS-20UC-PK
A34: D-BAT-V200 | B34: 585000 | C34: 20 | E34: =VLOOKUP(A34,PRODUCTOS!A:A,1,FALSE) -> D-BAT-V200 | L34: MS20UC-RD | M34: MS-20UC-RD
A35: D-BAT-V300 | B35: 338000 | C35: 20 | E35: =VLOOKUP(A35,PRODUCTOS!A:A,1,FALSE) -> D-BAT-V300 | L35: MS20UC-WE | M35: MS-20UC-WE
A36: D-BAT-V301 | B36: 533000 | C36: 20 | E36: =VLOOKUP(A36,PRODUCTOS!A:A,1,FALSE) -> D-BAT-V301 | L36: MW8V-BK | M36: MW-8V-BK
A37: D-CE18-BU | B37: 199900 | C37: 150 | E37: =VLOOKUP(A37,PRODUCTOS!A:A,1,FALSE) -> D-CE18-BU | L37: MW8V-WE | M37: MW-8V-WE
A38: D-CE24-BU | B38: 245900 | C38: 3 | E38: =VLOOKUP(A38,PRODUCTOS!A:A,1,FALSE) -> D-CE24-BU | L38: MX120B | M38: MX-120B
A39: D-CF1000 | B39: 29900 | C39: 875 | E39: =VLOOKUP(A39,PRODUCTOS!A:A,1,FALSE) -> D-CF1000 | L39: MX12B-GNRD | M39: MX-12B-GNRD
A40: D-CF2000 | B40: 159900 | C40: 731 | E40: =VLOOKUP(A40,PRODUCTOS!A:A,1,FALSE) -> D-CF2000 | L40: MX12B-PKLB | M40: MX-12B-PKLB
A41: D-CF3000 | B41: 369900 | C41: 88 | E41: =VLOOKUP(A41,PRODUCTOS!A:A,1,FALSE) -> D-CF3000 | L41: MX12B-WE | M41: MX-12B-WE
A42: D-CF4000-B | B42: 129900 | C42: 1065 | E42: =VLOOKUP(A42,PRODUCTOS!A:A,1,FALSE) -> D-CF4000-B | L42: XR-18WE1 | M42: XR-18WE1
...
